<?xml version="1.0" ?>
<!-- =================================================================================== -->
<!-- |    This document was autogenerated by xacro from innok_heros_3w.xacro           | -->
<!-- |    EDITING THIS FILE BY HAND IS NOT RECOMMENDED                                 | -->
<!-- =================================================================================== -->
<!--
Software License Agreement (BSD)

\authors Jonathan Hechtbauer
\maintainer Sabrina Heerklotz <sh@innok-robotics.de>
\copyright Copyright (c) 2015, Innok Robotics GmbH, All rights reserved

Redistribution and use in source and binary forms, with or without modification, are permitted provided that the following conditions are met:

1. Redistributions of source code must retain the above copyright notice, this list of conditions and the following disclaimer.

2. Redistributions in binary form must reproduce the above copyright notice, this list of conditions and the following disclaimer in the documentation and/or other materials provided with the distribution.

THIS SOFTWARE IS PROVIDED BY THE COPYRIGHT HOLDERS AND CONTRIBUTORS "AS IS" AND ANY EXPRESS OR IMPLIED WARRANTIES, INCLUDING, BUT NOT LIMITED TO, THE IMPLIED WARRANTIES OF MERCHANTABILITY AND FITNESS FOR A PARTICULAR PURPOSE ARE DISCLAIMED. IN NO EVENT SHALL THE COPYRIGHT HOLDER OR CONTRIBUTORS BE LIABLE FOR ANY DIRECT, INDIRECT, INCIDENTAL, SPECIAL, EXEMPLARY, OR CONSEQUENTIAL DAMAGES (INCLUDING, BUT NOT LIMITED TO, PROCUREMENT OF SUBSTITUTE GOODS OR SERVICES; LOSS OF USE, DATA, OR PROFITS; OR BUSINESS INTERRUPTION) HOWEVER CAUSED AND ON ANY THEORY OF LIABILITY, WHETHER IN CONTRACT, STRICT LIABILITY, OR TORT (INCLUDING NEGLIGENCE OR OTHERWISE) ARISING IN ANY WAY OUT OF THE USE OF THIS SOFTWARE, EVEN IF ADVISED OF THE POSSIBILITY OF SUCH DAMAGE.

-->
<robot name="innok_heros_3">
  <link name="base_link">
    <inertial>
      <origin rpy="0 0 0" xyz="0.40 0 0.02"/>
      <mass value="2"/>
      <inertia ixx="0.003" ixy="0" ixz="0" iyy="0.09" iyz="0" izz="0.09"/>
    </inertial>
    <visual>
      <origin rpy="0 0 0" xyz="0 0 0"/>
      <geometry>
        <mesh filename="package://innok_heros_description/meshes/base_link.STL"/>
      </geometry>
      <material name="white">
        <color rgba="1 1 1 1"/>
      </material>
    </visual>
    <collision>
      <origin rpy="0 0 0" xyz="0.4 0 0.02"/>
      <geometry>
        <box size="0.8 0.160 0.040"/>
      </geometry>
    </collision>
  </link>
  <link name="wheel_rear_left">
    <collision>
      <origin rpy="-1.5707963267948966 0 0" xyz="0 0.115 0"/>
      <geometry>
        <cylinder length="0.16" radius="0.16"/>
      </geometry>
    </collision>
    <visual>
      <origin rpy="0 0 0" xyz="0 0 0"/>
      <geometry>
        <mesh filename="package://innok_heros_description/meshes/wheel.STL"/>
      </geometry>
      <material name="">
        <color rgba="0.25 0.25 0.25 1"/>
      </material>
    </visual>
    <inertial>
      <origin rpy="0 0 0" xyz="0 0.115 0"/>
      <mass value="5.4"/>
      <inertia ixx="0.046" ixy="0" ixz="0" iyy="0.072" iyz="0" izz="0.045"/>
    </inertial>
  </link>
  <gazebo reference="wheel_rear_left">
    <gravity>true</gravity>
    <mu1>5</mu1>
    <mu2>5</mu2>
    <kd>1</kd>
    <kp>10000000000.0</kp>
    <fdir1>0 0 1</fdir1>
    <selfCollide>false</selfCollide>
    <material>Gazebo/Grey</material>
  </gazebo>
  <joint name="joint_base_wheel_rear_left" type="continuous">
    <parent link="drive_box_rear"/>
    <child link="wheel_rear_left"/>
    <origin rpy="0 0 0.0" xyz="0.063 0.162 -0.184"/>
    <axis xyz="0 1 0"/>
  </joint>
  <transmission name="trans_wheel_rear_left">
    <type>transmission_interface/SimpleTransmission</type>
    <joint name="joint_base_wheel_rear_left">
      <hardwareInterface>EffortJointInterface</hardwareInterface>
    </joint>
    <actuator name="motor_wheel_rear_left">
      <mechanicalReduction>100</mechanicalReduction>
    </actuator>
  </transmission>
  <link name="wheel_rear_right">
    <collision>
      <origin rpy="-1.5707963267948966 0 0" xyz="0 0.115 0"/>
      <geometry>
        <cylinder length="0.16" radius="0.16"/>
      </geometry>
    </collision>
    <visual>
      <origin rpy="0 0 0" xyz="0 0 0"/>
      <geometry>
        <mesh filename="package://innok_heros_description/meshes/wheel.STL"/>
      </geometry>
      <material name="">
        <color rgba="0.25 0.25 0.25 1"/>
      </material>
    </visual>
    <inertial>
      <origin rpy="0 0 0" xyz="0 0.115 0"/>
      <mass value="5.4"/>
      <inertia ixx="0.046" ixy="0" ixz="0" iyy="0.072" iyz="0" izz="0.045"/>
    </inertial>
  </link>
  <gazebo reference="wheel_rear_right">
    <gravity>true</gravity>
    <mu1>5</mu1>
    <mu2>5</mu2>
    <kd>1</kd>
    <kp>10000000000.0</kp>
    <fdir1>0 0 1</fdir1>
    <selfCollide>false</selfCollide>
    <material>Gazebo/Grey</material>
  </gazebo>
  <joint name="joint_base_wheel_rear_right" type="continuous">
    <parent link="drive_box_rear"/>
    <child link="wheel_rear_right"/>
    <origin rpy="0 0 3.141592653589793" xyz="0.063 -0.162 -0.184"/>
    <axis xyz="0 -1 0"/>
  </joint>
  <transmission name="trans_wheel_rear_right">
    <type>transmission_interface/SimpleTransmission</type>
    <joint name="joint_base_wheel_rear_right">
      <hardwareInterface>EffortJointInterface</hardwareInterface>
    </joint>
    <actuator name="motor_wheel_rear_right">
      <mechanicalReduction>100</mechanicalReduction>
    </actuator>
  </transmission>
  <link name="drive_box_rear">
    <inertial>
      <origin rpy="0 0 0" xyz="0.122 -0.0026 -0.136"/>
      <mass value="10.6"/>
      <inertia ixx="0.316" ixy="0" ixz="0" iyy="0.166" iyz="0" izz="0.307"/>
    </inertial>
    <visual>
      <origin rpy="0 0 0" xyz="0 0 0"/>
      <geometry>
        <mesh filename="package://innok_heros_description/meshes/drive_box.STL"/>
      </geometry>
      <material name="white">
        <color rgba="1 1 1 1"/>
      </material>
    </visual>
    <collision>
      <origin rpy="0 0 0" xyz="0.142 0 -0.124"/>
      <geometry>
        <box size="0.284 0.328 0.248"/>
      </geometry>
    </collision>
  </link>
  <joint name="drive_box_joint_rear" type="fixed">
    <origin rpy="0 0 0.0" xyz="0.018 0 -0.0065"/>
    <parent link="base_link"/>
    <child link="drive_box_rear"/>
    <axis xyz="0 0 0"/>
  </joint>
  <link name="caster_top">
    <inertial>
      <origin rpy="0 0 0" xyz="0.083 0 -0.024"/>
      <mass value="2.56"/>
      <inertia ixx="0.007" ixy="0" ixz="0" iyy="0.008" iyz="0" izz="0.014"/>
    </inertial>
    <visual>
      <origin rpy="0 0 0" xyz="0 0 0"/>
      <geometry>
        <mesh filename="package://innok_heros_description/meshes/caster_top.STL"/>
      </geometry>
      <material name="white">
        <color rgba="1 1 1 1"/>
      </material>
    </visual>
    <collision>
      <origin rpy="0 0 0" xyz="0.08 0 -0.025"/>
      <geometry>
        <box size="0.160 0.160 0.05"/>
      </geometry>
    </collision>
  </link>
  <joint name="caster_top_joint" type="fixed">
    <origin rpy="0 0 0" xyz="0.637 0 -0.006"/>
    <parent link="base_link"/>
    <child link="caster_top"/>
    <axis xyz="0 0 0"/>
  </joint>
  <link name="caster_bot">
    <inertial>
      <origin rpy="0 0 0" xyz="-0.023 0 -0.062"/>
      <mass value="2.9"/>
      <inertia ixx="0.016" ixy="0" ixz="0.005" iyy="0.016" iyz="0" izz="0.01"/>
    </inertial>
    <visual>
      <origin rpy="0 0 0" xyz="0 0 0"/>
      <geometry>
        <mesh filename="package://innok_heros_description/meshes/caster_bot.STL"/>
      </geometry>
      <material name="white">
        <color rgba="1 1 1 1"/>
      </material>
    </visual>
    <collision>
      <origin rpy="0 0 0" xyz="0 0 -0.05"/>
      <geometry>
        <cylinder length="0.09" radius="0.07"/>
      </geometry>
    </collision>
  </link>
  <joint name="caster_bot_joint" type="continuous">
    <origin rpy="0 0 0" xyz="0.083 0 -0.035"/>
    <parent link="caster_top"/>
    <child link="caster_bot"/>
    <axis xyz="0 0 1"/>
  </joint>
  <link name="caster_wheel">
    <inertial>
      <origin rpy="0 0 0" xyz="0 0 0"/>
      <mass value="5"/>
      <inertia ixx="0.017" ixy="0" ixz="0" iyy="0.030" iyz="0" izz="0.017"/>
    </inertial>
    <visual>
      <origin rpy="0 0 0" xyz="0 0 0"/>
      <geometry>
        <mesh filename="package://innok_heros_description/meshes/caster_wheel.STL"/>
      </geometry>
      <material name="">
        <color rgba="0.25 0.25 0.25 1"/>
      </material>
    </visual>
    <collision>
      <origin rpy="-1.57 0 0" xyz="0 0.01 0 "/>
      <geometry>
        <cylinder length="0.085" radius="0.125"/>
      </geometry>
    </collision>
  </link>
  <gazebo reference="caster_wheel">
    <!-- <mu1>0.2</mu1>
    <mu2>0.2</mu2>-->
    <material>Gazebo/Grey</material>
  </gazebo>
  <joint name="caster_wheel_joint" type="continuous">
    <origin rpy="0 0 0.003" xyz="-0.08 -0.014 -0.17"/>
    <parent link="caster_bot"/>
    <child link="caster_wheel"/>
    <axis xyz="0 1 0"/>
  </joint>
  &gt;

  
  <link name="battery_box">
    <inertial>
      <origin rpy="0 0 0" xyz="0.064 0 -0.1"/>
      <mass value="4.71"/>
      <inertia ixx="0.114" ixy="0" ixz="0" iyy="0.05" iyz="0" izz="0.078"/>
    </inertial>
    <visual>
      <origin rpy="0 0 0" xyz="0 0 0"/>
      <geometry>
        <mesh filename="package://innok_heros_description/meshes/battery_box.STL"/>
      </geometry>
      <material name="white">
        <color rgba="1 1 1 1"/>
      </material>
    </visual>
    <collision>
      <origin rpy="0 0 0" xyz="0.062 0 -0.124"/>
      <geometry>
        <box size="0.124 0.328 0.248"/>
      </geometry>
    </collision>
  </link>
  <joint name="battery_box_joint" type="fixed">
    <origin rpy="0 0 0" xyz="0.336 0 -0.007"/>
    <parent link="base_link"/>
    <child link="battery_box"/>
    <axis xyz="0 0 0"/>
  </joint>
  <link name="mounting_plate">
    <inertial>
      <origin rpy="0 0 0" xyz="0.319 0 -0.002"/>
      <mass value="4.35"/>
      <inertia ixx="0.133" ixy="0" ixz="0" iyy="0.278" iyz="0" izz="0.410"/>
    </inertial>
    <visual>
      <origin rpy="0 0 0" xyz="0 0 0"/>
      <geometry>
        <mesh filename="package://innok_heros_description/meshes/mounting_plate_3w.STL"/>
      </geometry>
      <material name="white">
        <color rgba="1 1 1 1"/>
      </material>
    </visual>
    <collision>
      <origin rpy="0 0 0" xyz="0.46 0 -0.002"/>
      <geometry>
        <box size="0.92 0.72 0.004"/>
      </geometry>
    </collision>
  </link>
  <joint name="mounting_plate_joint" type="fixed">
    <origin rpy="0 0 0" xyz=" -0.02 0 0.05"/>
    <parent link="base_link"/>
    <child link="mounting_plate"/>
    <axis xyz="0 0 0"/>
  </joint>
  <gazebo>
    <plugin filename="libgazebo_ros_joint_state_publisher.so" name="joint_state_publisher">
      <robotNamespace>/</robotNamespace>
      <jointName>joint_base_wheel_rear_left, joint_base_wheel_rear_right, caster_bot_joint, caster_wheel_joint</jointName>
      <updateRate>100.0</updateRate>
      <alwaysOn>true</alwaysOn>
    </plugin>
  </gazebo>
  <gazebo>
    <plugin filename="libgazebo_ros_diff_drive.so" name="differential_drive_controller">
      <alwaysOn>true</alwaysOn>
      <updateRate>100</updateRate>
      <leftJoint>joint_base_wheel_rear_right</leftJoint>
      <rightJoint>joint_base_wheel_rear_left</rightJoint>
      <wheelSeparation>0.580</wheelSeparation>
      <wheelDiameter>0.32</wheelDiameter>
      <wheelTorque>130</wheelTorque>
      <commandTopic>cmd_vel</commandTopic>
      <odometryTopic>odom</odometryTopic>
      <robotBaseFrame>base_link</robotBaseFrame>
    </plugin>
  </gazebo>
</robot>
